[2024-05-21T01:43:10.161+0000] {local_task_job_runner.py:120} INFO - ::group::Pre task execution logs
[2024-05-21T01:43:10.215+0000] {taskinstance.py:2076} INFO - Dependencies all met for dep_context=non-requeueable deps ti=<TaskInstance: log_analysis.tsla_log_analyzer manual__2024-05-21T01:43:08.459247+00:00 [queued]>
[2024-05-21T01:43:10.228+0000] {taskinstance.py:2076} INFO - Dependencies all met for dep_context=requeueable deps ti=<TaskInstance: log_analysis.tsla_log_analyzer manual__2024-05-21T01:43:08.459247+00:00 [queued]>
[2024-05-21T01:43:10.229+0000] {taskinstance.py:2306} INFO - Starting attempt 1 of 3
[2024-05-21T01:43:10.261+0000] {taskinstance.py:2330} INFO - Executing <Task(_PythonDecoratedOperator): tsla_log_analyzer> on 2024-05-21 01:43:08.459247+00:00
[2024-05-21T01:43:10.272+0000] {standard_task_runner.py:90} INFO - Running: ['***', 'tasks', 'run', 'log_analysis', 'tsla_log_analyzer', 'manual__2024-05-21T01:43:08.459247+00:00', '--job-id', '45', '--raw', '--subdir', 'DAGS_FOLDER/log-analysis.py', '--cfg-path', '/tmp/tmp856lz8j0']
[2024-05-21T01:43:10.274+0000] {logging_mixin.py:188} WARNING - /home/***/.local/lib/python3.12/site-packages/***/task/task_runner/standard_task_runner.py:61 DeprecationWarning: This process (pid=1358) is multi-threaded, use of fork() may lead to deadlocks in the child.
[2024-05-21T01:43:10.275+0000] {standard_task_runner.py:91} INFO - Job 45: Subtask tsla_log_analyzer
[2024-05-21T01:43:10.275+0000] {standard_task_runner.py:63} INFO - Started process 1360 to run task
[2024-05-21T01:43:10.344+0000] {task_command.py:426} INFO - Running <TaskInstance: log_analysis.tsla_log_analyzer manual__2024-05-21T01:43:08.459247+00:00 [running]> on host dc88ed38eb65
[2024-05-21T01:43:10.502+0000] {taskinstance.py:2648} INFO - Exporting env vars: AIRFLOW_CTX_DAG_OWNER='***' AIRFLOW_CTX_DAG_ID='log_analysis' AIRFLOW_CTX_TASK_ID='tsla_log_analyzer' AIRFLOW_CTX_EXECUTION_DATE='2024-05-21T01:43:08.459247+00:00' AIRFLOW_CTX_TRY_NUMBER='1' AIRFLOW_CTX_DAG_RUN_ID='manual__2024-05-21T01:43:08.459247+00:00'
[2024-05-21T01:43:10.503+0000] {taskinstance.py:430} INFO - ::endgroup::
[2024-05-21T01:43:10.719+0000] {logging_mixin.py:188} INFO - Log error summary for task: get_tesla_data
[2024-05-21T01:43:10.720+0000] {logging_mixin.py:188} INFO - Total number of errors: 4
[2024-05-21T01:43:10.720+0000] {logging_mixin.py:188} INFO - Here are all the errors:
[2024-05-21T01:43:10.722+0000] {logging_mixin.py:188} INFO - [2024-05-18T20:14:34.556+0000] {taskinstance.py:2905} ERROR - Task failed with exception
[2024-05-21T01:43:10.723+0000] {logging_mixin.py:188} INFO - [2024-05-18T20:14:34.612+0000] {standard_task_runner.py:110} ERROR - Failed to execute job 7 for task get_tesla_data (Cannot save file into a non-existent directory: '/tmp/data/{ ds }'; 1657)
[2024-05-21T01:43:10.724+0000] {logging_mixin.py:188} INFO - [2024-05-18T21:32:06.418+0000] {taskinstance.py:2905} ERROR - Task failed with exception
[2024-05-21T01:43:10.725+0000] {logging_mixin.py:188} INFO - [2024-05-18T21:32:06.464+0000] {standard_task_runner.py:110} ERROR - Failed to execute job 42 for task get_tesla_data (Cannot save file into a non-existent directory: '/opt/***/temp_data/2024-05-18'; 689)
[2024-05-21T01:43:10.725+0000] {python.py:237} INFO - Done. Returned value was: None
[2024-05-21T01:43:10.727+0000] {taskinstance.py:441} INFO - ::group::Post task execution logs
[2024-05-21T01:43:10.743+0000] {taskinstance.py:1206} INFO - Marking task as SUCCESS. dag_id=log_analysis, task_id=tsla_log_analyzer, run_id=manual__2024-05-21T01:43:08.459247+00:00, execution_date=20240521T014308, start_date=20240521T014310, end_date=20240521T014310
[2024-05-21T01:43:10.811+0000] {local_task_job_runner.py:240} INFO - Task exited with return code 0
[2024-05-21T01:43:10.836+0000] {taskinstance.py:3498} INFO - 0 downstream tasks scheduled from follow-on schedule check
[2024-05-21T01:43:10.841+0000] {local_task_job_runner.py:222} INFO - ::endgroup::
