[2024-05-21T01:43:10.162+0000] {local_task_job_runner.py:120} INFO - ::group::Pre task execution logs
[2024-05-21T01:43:10.216+0000] {taskinstance.py:2076} INFO - Dependencies all met for dep_context=non-requeueable deps ti=<TaskInstance: log_analysis.appl_log_analyzer manual__2024-05-21T01:43:08.459247+00:00 [queued]>
[2024-05-21T01:43:10.228+0000] {taskinstance.py:2076} INFO - Dependencies all met for dep_context=requeueable deps ti=<TaskInstance: log_analysis.appl_log_analyzer manual__2024-05-21T01:43:08.459247+00:00 [queued]>
[2024-05-21T01:43:10.229+0000] {taskinstance.py:2306} INFO - Starting attempt 1 of 3
[2024-05-21T01:43:10.252+0000] {taskinstance.py:2330} INFO - Executing <Task(_PythonDecoratedOperator): appl_log_analyzer> on 2024-05-21 01:43:08.459247+00:00
[2024-05-21T01:43:10.261+0000] {standard_task_runner.py:90} INFO - Running: ['***', 'tasks', 'run', 'log_analysis', 'appl_log_analyzer', 'manual__2024-05-21T01:43:08.459247+00:00', '--job-id', '46', '--raw', '--subdir', 'DAGS_FOLDER/log-analysis.py', '--cfg-path', '/tmp/tmpcolvdzl6']
[2024-05-21T01:43:10.265+0000] {logging_mixin.py:188} WARNING - /home/***/.local/lib/python3.12/site-packages/***/task/task_runner/standard_task_runner.py:61 DeprecationWarning: This process (pid=1357) is multi-threaded, use of fork() may lead to deadlocks in the child.
[2024-05-21T01:43:10.266+0000] {standard_task_runner.py:91} INFO - Job 46: Subtask appl_log_analyzer
[2024-05-21T01:43:10.266+0000] {standard_task_runner.py:63} INFO - Started process 1359 to run task
[2024-05-21T01:43:10.333+0000] {task_command.py:426} INFO - Running <TaskInstance: log_analysis.appl_log_analyzer manual__2024-05-21T01:43:08.459247+00:00 [running]> on host dc88ed38eb65
[2024-05-21T01:43:10.492+0000] {taskinstance.py:2648} INFO - Exporting env vars: AIRFLOW_CTX_DAG_OWNER='***' AIRFLOW_CTX_DAG_ID='log_analysis' AIRFLOW_CTX_TASK_ID='appl_log_analyzer' AIRFLOW_CTX_EXECUTION_DATE='2024-05-21T01:43:08.459247+00:00' AIRFLOW_CTX_TRY_NUMBER='1' AIRFLOW_CTX_DAG_RUN_ID='manual__2024-05-21T01:43:08.459247+00:00'
[2024-05-21T01:43:10.494+0000] {taskinstance.py:430} INFO - ::endgroup::
[2024-05-21T01:43:10.700+0000] {logging_mixin.py:188} INFO - Log error summary for task: get_apple_data
[2024-05-21T01:43:10.701+0000] {logging_mixin.py:188} INFO - Total number of errors: 4
[2024-05-21T01:43:10.702+0000] {logging_mixin.py:188} INFO - Here are all the errors:
[2024-05-21T01:43:10.702+0000] {logging_mixin.py:188} INFO - [2024-05-18T20:14:34.663+0000] {taskinstance.py:2905} ERROR - Task failed with exception
[2024-05-21T01:43:10.703+0000] {logging_mixin.py:188} INFO - [2024-05-18T20:14:34.704+0000] {standard_task_runner.py:110} ERROR - Failed to execute job 8 for task get_apple_data (Cannot save file into a non-existent directory: '/tmp/data/{ ds }'; 1656)
[2024-05-21T01:43:10.704+0000] {logging_mixin.py:188} INFO - [2024-05-18T21:32:06.366+0000] {taskinstance.py:2905} ERROR - Task failed with exception
[2024-05-21T01:43:10.705+0000] {logging_mixin.py:188} INFO - [2024-05-18T21:32:06.419+0000] {standard_task_runner.py:110} ERROR - Failed to execute job 43 for task get_apple_data (Cannot save file into a non-existent directory: '/opt/***/temp_data/2024-05-18'; 690)
[2024-05-21T01:43:10.706+0000] {python.py:237} INFO - Done. Returned value was: None
[2024-05-21T01:43:10.708+0000] {taskinstance.py:441} INFO - ::group::Post task execution logs
[2024-05-21T01:43:10.724+0000] {taskinstance.py:1206} INFO - Marking task as SUCCESS. dag_id=log_analysis, task_id=appl_log_analyzer, run_id=manual__2024-05-21T01:43:08.459247+00:00, execution_date=20240521T014308, start_date=20240521T014310, end_date=20240521T014310
[2024-05-21T01:43:10.766+0000] {local_task_job_runner.py:240} INFO - Task exited with return code 0
[2024-05-21T01:43:10.790+0000] {taskinstance.py:3498} INFO - 0 downstream tasks scheduled from follow-on schedule check
[2024-05-21T01:43:10.792+0000] {local_task_job_runner.py:222} INFO - ::endgroup::
